2024-08-15 20:18:23,065 - INFO - Starting data extraction...
2024-08-15 20:18:23,065 - DEBUG - Loading the flight data from the directory: ['Flight1.csv', 'Flight2.csv', 'Flight3.csv', 'Flight4.csv', 'Flight5.csv', 'Flight6.csv', 'Flight7.csv', 'Flight8.csv', 'Flight9.csv', 'Flight10.csv', 'Flight11.csv', 'Flight12.csv']
2024-08-15 20:18:23,065 - ERROR - Error loading the flight data
Traceback (most recent call last):
  File "/Users/erinkeane/Desktop/INST414/inst414-final-project-Erin-Keane/etl/extract.py", line 45, in load_flight_data
    flight_df = [pd.read_csv(data_directory / file) for file in flight_files]
                ^^^^^^^^^^^^^^^^^^^^^^^^^^^^^^^^^^^^^^^^^^^^^^^^^^^^^^^^^^^^^
  File "/Users/erinkeane/Desktop/INST414/inst414-final-project-Erin-Keane/etl/extract.py", line 45, in <listcomp>
    flight_df = [pd.read_csv(data_directory / file) for file in flight_files]
                 ^^^^^^^^^^^^^^^^^^^^^^^^^^^^^^^^^^
  File "/Users/erinkeane/Desktop/INST414/.venv/lib/python3.11/site-packages/pandas/io/parsers/readers.py", line 1026, in read_csv
    return _read(filepath_or_buffer, kwds)
           ^^^^^^^^^^^^^^^^^^^^^^^^^^^^^^^
  File "/Users/erinkeane/Desktop/INST414/.venv/lib/python3.11/site-packages/pandas/io/parsers/readers.py", line 620, in _read
    parser = TextFileReader(filepath_or_buffer, **kwds)
             ^^^^^^^^^^^^^^^^^^^^^^^^^^^^^^^^^^^^^^^^^^
  File "/Users/erinkeane/Desktop/INST414/.venv/lib/python3.11/site-packages/pandas/io/parsers/readers.py", line 1620, in __init__
    self._engine = self._make_engine(f, self.engine)
                   ^^^^^^^^^^^^^^^^^^^^^^^^^^^^^^^^^
  File "/Users/erinkeane/Desktop/INST414/.venv/lib/python3.11/site-packages/pandas/io/parsers/readers.py", line 1880, in _make_engine
    self.handles = get_handle(
                   ^^^^^^^^^^^
  File "/Users/erinkeane/Desktop/INST414/.venv/lib/python3.11/site-packages/pandas/io/common.py", line 873, in get_handle
    handle = open(
             ^^^^^
FileNotFoundError: [Errno 2] No such file or directory: '../data/original data/Flight1.csv'
2024-08-15 20:18:23,066 - ERROR - Error processing data
Traceback (most recent call last):
  File "/Users/erinkeane/Desktop/INST414/inst414-final-project-Erin-Keane/etl/extract.py", line 81, in process_data
    flight_data = load_flight_data()
                  ^^^^^^^^^^^^^^^^^^
  File "/Users/erinkeane/Desktop/INST414/inst414-final-project-Erin-Keane/etl/extract.py", line 45, in load_flight_data
    flight_df = [pd.read_csv(data_directory / file) for file in flight_files]
                ^^^^^^^^^^^^^^^^^^^^^^^^^^^^^^^^^^^^^^^^^^^^^^^^^^^^^^^^^^^^^
  File "/Users/erinkeane/Desktop/INST414/inst414-final-project-Erin-Keane/etl/extract.py", line 45, in <listcomp>
    flight_df = [pd.read_csv(data_directory / file) for file in flight_files]
                 ^^^^^^^^^^^^^^^^^^^^^^^^^^^^^^^^^^
  File "/Users/erinkeane/Desktop/INST414/.venv/lib/python3.11/site-packages/pandas/io/parsers/readers.py", line 1026, in read_csv
    return _read(filepath_or_buffer, kwds)
           ^^^^^^^^^^^^^^^^^^^^^^^^^^^^^^^
  File "/Users/erinkeane/Desktop/INST414/.venv/lib/python3.11/site-packages/pandas/io/parsers/readers.py", line 620, in _read
    parser = TextFileReader(filepath_or_buffer, **kwds)
             ^^^^^^^^^^^^^^^^^^^^^^^^^^^^^^^^^^^^^^^^^^
  File "/Users/erinkeane/Desktop/INST414/.venv/lib/python3.11/site-packages/pandas/io/parsers/readers.py", line 1620, in __init__
    self._engine = self._make_engine(f, self.engine)
                   ^^^^^^^^^^^^^^^^^^^^^^^^^^^^^^^^^
  File "/Users/erinkeane/Desktop/INST414/.venv/lib/python3.11/site-packages/pandas/io/parsers/readers.py", line 1880, in _make_engine
    self.handles = get_handle(
                   ^^^^^^^^^^^
  File "/Users/erinkeane/Desktop/INST414/.venv/lib/python3.11/site-packages/pandas/io/common.py", line 873, in get_handle
    handle = open(
             ^^^^^
FileNotFoundError: [Errno 2] No such file or directory: '../data/original data/Flight1.csv'
2024-08-15 20:18:23,066 - ERROR - An error occurred during the process
Traceback (most recent call last):
  File "/Users/erinkeane/Desktop/INST414/inst414-final-project-Erin-Keane/main.py", line 39, in main
    extract_data()
  File "/Users/erinkeane/Desktop/INST414/inst414-final-project-Erin-Keane/etl/extract.py", line 81, in process_data
    flight_data = load_flight_data()
                  ^^^^^^^^^^^^^^^^^^
  File "/Users/erinkeane/Desktop/INST414/inst414-final-project-Erin-Keane/etl/extract.py", line 45, in load_flight_data
    flight_df = [pd.read_csv(data_directory / file) for file in flight_files]
                ^^^^^^^^^^^^^^^^^^^^^^^^^^^^^^^^^^^^^^^^^^^^^^^^^^^^^^^^^^^^^
  File "/Users/erinkeane/Desktop/INST414/inst414-final-project-Erin-Keane/etl/extract.py", line 45, in <listcomp>
    flight_df = [pd.read_csv(data_directory / file) for file in flight_files]
                 ^^^^^^^^^^^^^^^^^^^^^^^^^^^^^^^^^^
  File "/Users/erinkeane/Desktop/INST414/.venv/lib/python3.11/site-packages/pandas/io/parsers/readers.py", line 1026, in read_csv
    return _read(filepath_or_buffer, kwds)
           ^^^^^^^^^^^^^^^^^^^^^^^^^^^^^^^
  File "/Users/erinkeane/Desktop/INST414/.venv/lib/python3.11/site-packages/pandas/io/parsers/readers.py", line 620, in _read
    parser = TextFileReader(filepath_or_buffer, **kwds)
             ^^^^^^^^^^^^^^^^^^^^^^^^^^^^^^^^^^^^^^^^^^
  File "/Users/erinkeane/Desktop/INST414/.venv/lib/python3.11/site-packages/pandas/io/parsers/readers.py", line 1620, in __init__
    self._engine = self._make_engine(f, self.engine)
                   ^^^^^^^^^^^^^^^^^^^^^^^^^^^^^^^^^
  File "/Users/erinkeane/Desktop/INST414/.venv/lib/python3.11/site-packages/pandas/io/parsers/readers.py", line 1880, in _make_engine
    self.handles = get_handle(
                   ^^^^^^^^^^^
  File "/Users/erinkeane/Desktop/INST414/.venv/lib/python3.11/site-packages/pandas/io/common.py", line 873, in get_handle
    handle = open(
             ^^^^^
FileNotFoundError: [Errno 2] No such file or directory: '../data/original data/Flight1.csv'
